<mujoco model="push_button">
  <option gravity="0 0 0" />

  <worldbody>
    <body>
      <body name="object" pos="0 0 0.01">
        <geom name="base_geom" type="box" size="0.03 0.03 0.01" rgba="0 0 1 1" mass="10000"
          group="0" />

        <body name="button" pos="0 0 0.035">
          <joint name="btn_slide" type="slide" axis="0 0 1" range="-0.02 0.0" damping="2"
            stiffness="20" />
          <geom name="btn" type="cylinder" size="0.02 0.005" rgba="1 0 0 1" group="0" />
        </body>
      </body>
      <site rgba="0 0 0 0" size="0.002" pos="0 0 0" name="bottom_site" />
      <site rgba="0 0 0 0" size="0.002" pos="0 0 0.05" name="top_site" />
      <site rgba="0 0 0 0" size="0.002" pos="0.0 0.05 0"
        name="horizontal_radius_site" />
    </body>
  </worldbody>
</mujoco>