<mujoco model="three_drawer_cabinet">
  <asset>
    <texture name="wood_tex" type="2d" file="../textures/wood-tiles.png" />
    <material name="wood_mat" texture="wood_tex" specular="0.3" shininess="0.1" rgba="1 1 1 1" />
    <texture name="metal_tex" type="2d" file="../textures/steel-brushed.png" />
    <material name="metal_mat" texture="metal_tex" specular="0.9" shininess="80"
      rgba="0.7 0.7 0.7 1" />
  </asset>
  <worldbody>
    <body>
      <body name="object" pos="0 0 0.00">
        <geom name="cab_side_L" type="box" pos="0.095 0 0.105" size="0.005 0.10 0.10"
          material="wood_mat" density="500000" group="0" />
        <geom name="cab_side_R" type="box" pos="-0.095 0 0.105" size="0.005 0.10 0.10"
          material="wood_mat" density="500000" group="0" />
        <geom name="cab_bottom" type="box" pos="0 0 0" size="0.10 0.10 0.005"
          material="wood_mat" density="500000" group="0" />
        <geom name="cab_top" type="box" pos="0 0 0.21" size="0.10 0.10 0.005"
          material="wood_mat" density="500000" group="0" />

        <body name="drawer1" pos="0 0 0.05">
          <joint name="drawer1_slide" type="slide" axis="0 1 0" range="0 0.19"
            damping="0.05" stiffness="20" />
          <geom name="d1_left" type="box" pos="0.090 0 0" size="0.005 0.090 0.05"
            material="wood_mat" density="500" group="0" />
          <geom name="d1_right" type="box" pos="-0.090 0 0" size="0.005 0.090 0.05"
            material="wood_mat" density="500" group="0" />
          <geom name="d1_back" type="box" pos="0 -0.090 0" size="0.090 0.005 0.05"
            material="wood_mat" density="500" group="0" />
          <geom name="d1_front" type="box" pos="0 0.090 0" size="0.090 0.005 0.05"
            material="wood_mat" density="500" group="0" />
          <geom name="d1_bottom" type="box" pos="0 0 -0.045" size="0.090 0.090 0.005"
            material="wood_mat" density="500" group="0" />
          <geom name="d1_handle" type="box" pos="0 0.11 0" size="0.02 0.01 0.01"
            material="metal_mat" density="500" group="0" />
        </body>

        <body name="drawer2" pos="0 0 0.153">
          <joint name="drawer2_slide" type="slide" axis="0 1 0" range="0 0.19"
            damping="0.05" frictionloss="0.3" />
          <geom name="d2_left" type="box" pos="0.090 0 0" size="0.005 0.090 0.05"
            material="wood_mat" density="500" group="0" />
          <geom name="d2_right" type="box" pos="-0.090 0 0" size="0.005 0.090 0.05"
            material="wood_mat" density="500" group="0" />
          <geom name="d2_back" type="box" pos="0 -0.090 0" size="0.090 0.005 0.05"
            material="wood_mat" density="500" group="0" />
          <geom name="d2_front" type="box" pos="0 0.090 0" size="0.090 0.005 0.05"
            material="wood_mat" density="500" group="0" />
          <geom name="d2_bottom" type="box" pos="0 0 -0.045" size="0.090 0.090 0.005"
            material="wood_mat" density="500" group="0" />
          <geom name="d2_handle" type="box" pos="0 0.11 0" size="0.02 0.01 0.01"
            material="metal_mat" density="500" group="0" rgba="0.3 0.3 0.8 1" />
        </body>

      </body>

      <site rgba="0 0 0 0" size="0.005" pos="0 0 0" name="bottom_site" />
      <site rgba="0 0 0 0" size="0.005" pos="0 0 0.2" name="top_site" />
      <site rgba="0 0 0 0" size="0.005" pos="0.1 0.05 0"
        name="horizontal_radius_site" />
    </body>
  </worldbody>
</mujoco>